Traceback (most recent call last):
  File "/home/runner/micromamba/envs/data_science/lib/python3.10/site-packages/jupyter_cache/executors/utils.py", line 58, in single_nb_execution
    executenb(
  File "/home/runner/micromamba/envs/data_science/lib/python3.10/site-packages/nbclient/client.py", line 1314, in execute
    return NotebookClient(nb=nb, resources=resources, km=km, **kwargs).execute()
  File "/home/runner/micromamba/envs/data_science/lib/python3.10/site-packages/jupyter_core/utils/__init__.py", line 165, in wrapped
    return loop.run_until_complete(inner)
  File "/home/runner/micromamba/envs/data_science/lib/python3.10/asyncio/base_events.py", line 649, in run_until_complete
    return future.result()
  File "/home/runner/micromamba/envs/data_science/lib/python3.10/site-packages/nbclient/client.py", line 709, in async_execute
    await self.async_execute_cell(
  File "/home/runner/micromamba/envs/data_science/lib/python3.10/site-packages/nbclient/client.py", line 1062, in async_execute_cell
    await self._check_raise_for_error(cell, cell_index, exec_reply)
  File "/home/runner/micromamba/envs/data_science/lib/python3.10/site-packages/nbclient/client.py", line 918, in _check_raise_for_error
    raise CellExecutionError.from_cell_and_msg(cell, exec_reply_content)
nbclient.exceptions.CellExecutionError: An error occurred while executing the following cell:
------------------
filename = "../datasets/tripadvisor_hotel_reviews.csv"
data = pd.read_csv(filename)
data.head()
------------------


[0;31m---------------------------------------------------------------------------[0m
[0;31mUnicodeDecodeError[0m                        Traceback (most recent call last)
Cell [0;32mIn[4], line 2[0m
[1;32m      1[0m filename [38;5;241m=[39m [38;5;124m"[39m[38;5;124m../datasets/tripadvisor_hotel_reviews.csv[39m[38;5;124m"[39m
[0;32m----> 2[0m data [38;5;241m=[39m [43mpd[49m[38;5;241;43m.[39;49m[43mread_csv[49m[43m([49m[43mfilename[49m[43m)[49m
[1;32m      3[0m data[38;5;241m.[39mhead()

File [0;32m~/micromamba/envs/data_science/lib/python3.10/site-packages/pandas/io/parsers/readers.py:1026[0m, in [0;36mread_csv[0;34m(filepath_or_buffer, sep, delimiter, header, names, index_col, usecols, dtype, engine, converters, true_values, false_values, skipinitialspace, skiprows, skipfooter, nrows, na_values, keep_default_na, na_filter, verbose, skip_blank_lines, parse_dates, infer_datetime_format, keep_date_col, date_parser, date_format, dayfirst, cache_dates, iterator, chunksize, compression, thousands, decimal, lineterminator, quotechar, quoting, doublequote, escapechar, comment, encoding, encoding_errors, dialect, on_bad_lines, delim_whitespace, low_memory, memory_map, float_precision, storage_options, dtype_backend)[0m
[1;32m   1013[0m kwds_defaults [38;5;241m=[39m _refine_defaults_read(
[1;32m   1014[0m     dialect,
[1;32m   1015[0m     delimiter,
[0;32m   (...)[0m
[1;32m   1022[0m     dtype_backend[38;5;241m=[39mdtype_backend,
[1;32m   1023[0m )
[1;32m   1024[0m kwds[38;5;241m.[39mupdate(kwds_defaults)
[0;32m-> 1026[0m [38;5;28;01mreturn[39;00m [43m_read[49m[43m([49m[43mfilepath_or_buffer[49m[43m,[49m[43m [49m[43mkwds[49m[43m)[49m

File [0;32m~/micromamba/envs/data_science/lib/python3.10/site-packages/pandas/io/parsers/readers.py:620[0m, in [0;36m_read[0;34m(filepath_or_buffer, kwds)[0m
[1;32m    617[0m _validate_names(kwds[38;5;241m.[39mget([38;5;124m"[39m[38;5;124mnames[39m[38;5;124m"[39m, [38;5;28;01mNone[39;00m))
[1;32m    619[0m [38;5;66;03m# Create the parser.[39;00m
[0;32m--> 620[0m parser [38;5;241m=[39m [43mTextFileReader[49m[43m([49m[43mfilepath_or_buffer[49m[43m,[49m[43m [49m[38;5;241;43m*[39;49m[38;5;241;43m*[39;49m[43mkwds[49m[43m)[49m
[1;32m    622[0m [38;5;28;01mif[39;00m chunksize [38;5;129;01mor[39;00m iterator:
[1;32m    623[0m     [38;5;28;01mreturn[39;00m parser

File [0;32m~/micromamba/envs/data_science/lib/python3.10/site-packages/pandas/io/parsers/readers.py:1620[0m, in [0;36mTextFileReader.__init__[0;34m(self, f, engine, **kwds)[0m
[1;32m   1617[0m     [38;5;28mself[39m[38;5;241m.[39moptions[[38;5;124m"[39m[38;5;124mhas_index_names[39m[38;5;124m"[39m] [38;5;241m=[39m kwds[[38;5;124m"[39m[38;5;124mhas_index_names[39m[38;5;124m"[39m]
[1;32m   1619[0m [38;5;28mself[39m[38;5;241m.[39mhandles: IOHandles [38;5;241m|[39m [38;5;28;01mNone[39;00m [38;5;241m=[39m [38;5;28;01mNone[39;00m
[0;32m-> 1620[0m [38;5;28mself[39m[38;5;241m.[39m_engine [38;5;241m=[39m [38;5;28;43mself[39;49m[38;5;241;43m.[39;49m[43m_make_engine[49m[43m([49m[43mf[49m[43m,[49m[43m [49m[38;5;28;43mself[39;49m[38;5;241;43m.[39;49m[43mengine[49m[43m)[49m

File [0;32m~/micromamba/envs/data_science/lib/python3.10/site-packages/pandas/io/parsers/readers.py:1898[0m, in [0;36mTextFileReader._make_engine[0;34m(self, f, engine)[0m
[1;32m   1895[0m     [38;5;28;01mraise[39;00m [38;5;167;01mValueError[39;00m(msg)
[1;32m   1897[0m [38;5;28;01mtry[39;00m:
[0;32m-> 1898[0m     [38;5;28;01mreturn[39;00m [43mmapping[49m[43m[[49m[43mengine[49m[43m][49m[43m([49m[43mf[49m[43m,[49m[43m [49m[38;5;241;43m*[39;49m[38;5;241;43m*[39;49m[38;5;28;43mself[39;49m[38;5;241;43m.[39;49m[43moptions[49m[43m)[49m
[1;32m   1899[0m [38;5;28;01mexcept[39;00m [38;5;167;01mException[39;00m:
[1;32m   1900[0m     [38;5;28;01mif[39;00m [38;5;28mself[39m[38;5;241m.[39mhandles [38;5;129;01mis[39;00m [38;5;129;01mnot[39;00m [38;5;28;01mNone[39;00m:

File [0;32m~/micromamba/envs/data_science/lib/python3.10/site-packages/pandas/io/parsers/c_parser_wrapper.py:93[0m, in [0;36mCParserWrapper.__init__[0;34m(self, src, **kwds)[0m
[1;32m     90[0m [38;5;28;01mif[39;00m kwds[[38;5;124m"[39m[38;5;124mdtype_backend[39m[38;5;124m"[39m] [38;5;241m==[39m [38;5;124m"[39m[38;5;124mpyarrow[39m[38;5;124m"[39m:
[1;32m     91[0m     [38;5;66;03m# Fail here loudly instead of in cython after reading[39;00m
[1;32m     92[0m     import_optional_dependency([38;5;124m"[39m[38;5;124mpyarrow[39m[38;5;124m"[39m)
[0;32m---> 93[0m [38;5;28mself[39m[38;5;241m.[39m_reader [38;5;241m=[39m [43mparsers[49m[38;5;241;43m.[39;49m[43mTextReader[49m[43m([49m[43msrc[49m[43m,[49m[43m [49m[38;5;241;43m*[39;49m[38;5;241;43m*[39;49m[43mkwds[49m[43m)[49m
[1;32m     95[0m [38;5;28mself[39m[38;5;241m.[39munnamed_cols [38;5;241m=[39m [38;5;28mself[39m[38;5;241m.[39m_reader[38;5;241m.[39munnamed_cols
[1;32m     97[0m [38;5;66;03m# error: Cannot determine type of 'names'[39;00m

File [0;32mparsers.pyx:574[0m, in [0;36mpandas._libs.parsers.TextReader.__cinit__[0;34m()[0m

File [0;32mparsers.pyx:663[0m, in [0;36mpandas._libs.parsers.TextReader._get_header[0;34m()[0m

File [0;32mparsers.pyx:874[0m, in [0;36mpandas._libs.parsers.TextReader._tokenize_rows[0;34m()[0m

File [0;32mparsers.pyx:891[0m, in [0;36mpandas._libs.parsers.TextReader._check_tokenize_status[0;34m()[0m

File [0;32mparsers.pyx:2053[0m, in [0;36mpandas._libs.parsers.raise_parser_error[0;34m()[0m

[0;31mUnicodeDecodeError[0m: 'utf-8' codec can't decode byte 0xc7 in position 10968: invalid continuation byte

