Traceback (most recent call last):
  File "/home/runner/micromamba/envs/data_science/lib/python3.10/site-packages/jupyter_cache/executors/utils.py", line 58, in single_nb_execution
    executenb(
  File "/home/runner/micromamba/envs/data_science/lib/python3.10/site-packages/nbclient/client.py", line 1314, in execute
    return NotebookClient(nb=nb, resources=resources, km=km, **kwargs).execute()
  File "/home/runner/micromamba/envs/data_science/lib/python3.10/site-packages/jupyter_core/utils/__init__.py", line 165, in wrapped
    return loop.run_until_complete(inner)
  File "/home/runner/micromamba/envs/data_science/lib/python3.10/asyncio/base_events.py", line 649, in run_until_complete
    return future.result()
  File "/home/runner/micromamba/envs/data_science/lib/python3.10/site-packages/nbclient/client.py", line 709, in async_execute
    await self.async_execute_cell(
  File "/home/runner/micromamba/envs/data_science/lib/python3.10/site-packages/nbclient/client.py", line 1062, in async_execute_cell
    await self._check_raise_for_error(cell, cell_index, exec_reply)
  File "/home/runner/micromamba/envs/data_science/lib/python3.10/site-packages/nbclient/client.py", line 918, in _check_raise_for_error
    raise CellExecutionError.from_cell_and_msg(cell, exec_reply_content)
nbclient.exceptions.CellExecutionError: An error occurred while executing the following cell:
------------------
sb.pairplot(data, height=4)
plt.show()
------------------


[0;31m---------------------------------------------------------------------------[0m
[0;31mTypeError[0m                                 Traceback (most recent call last)
Cell [0;32mIn[14], line 1[0m
[0;32m----> 1[0m [43msb[49m[38;5;241;43m.[39;49m[43mpairplot[49m[43m([49m[43mdata[49m[43m,[49m[43m [49m[43mheight[49m[38;5;241;43m=[39;49m[38;5;241;43m4[39;49m[43m)[49m
[1;32m      2[0m plt[38;5;241m.[39mshow()

File [0;32m~/micromamba/envs/data_science/lib/python3.10/site-packages/seaborn/axisgrid.py:2103[0m, in [0;36mpairplot[0;34m(data, hue, hue_order, palette, vars, x_vars, y_vars, kind, diag_kind, markers, height, aspect, corner, dropna, plot_kws, diag_kws, grid_kws, size)[0m
[1;32m   2100[0m     warnings[38;5;241m.[39mwarn(msg, [38;5;167;01mUserWarning[39;00m)
[1;32m   2102[0m [38;5;28;01mif[39;00m [38;5;129;01mnot[39;00m [38;5;28misinstance[39m(data, pd[38;5;241m.[39mDataFrame):
[0;32m-> 2103[0m     [38;5;28;01mraise[39;00m [38;5;167;01mTypeError[39;00m(
[1;32m   2104[0m         [38;5;124mf[39m[38;5;124m"[39m[38;5;124m'[39m[38;5;124mdata[39m[38;5;124m'[39m[38;5;124m must be pandas DataFrame object, not: [39m[38;5;132;01m{[39;00m[38;5;28mtype[39m(data)[38;5;132;01m}[39;00m[38;5;124m"[39m)
[1;32m   2106[0m plot_kws [38;5;241m=[39m {} [38;5;28;01mif[39;00m plot_kws [38;5;129;01mis[39;00m [38;5;28;01mNone[39;00m [38;5;28;01melse[39;00m plot_kws[38;5;241m.[39mcopy()
[1;32m   2107[0m diag_kws [38;5;241m=[39m {} [38;5;28;01mif[39;00m diag_kws [38;5;129;01mis[39;00m [38;5;28;01mNone[39;00m [38;5;28;01melse[39;00m diag_kws[38;5;241m.[39mcopy()

[0;31mTypeError[0m: 'data' must be pandas DataFrame object, not: <class 'dict'>

